<?xml version="1.0" encoding="utf-8"?>
<!-- =================================================================================== -->
<!-- |    This document was autogenerated by xacro from src/myrobot_description/urdf/myrobot.xacro | -->
<!-- |    EDITING THIS FILE BY HAND IS NOT RECOMMENDED                                 | -->
<!-- =================================================================================== -->
<robot name="mytank">
  <material name="blue">
    <color rgba="0.0 0.0 0.8 1.0"/>
  </material>
  <material name="white">
    <color rgba="1.0 1.0 1.0 1.0"/>
  </material>
  <material name="red">
    <color rgba="0.8 0.0 0.0 1.0"/>
  </material>
  <material name="green">
    <color rgba="0.0 0.8 0.0 1.0"/>
  </material>
  <material name="black">
    <color rgba="0.0 0.0 0.0 1.0"/>
  </material>
  <!--  model  begin-->
  <link name="base_link">
    <origin rpy="0.0 0.0 0.0" xyz="0.0 0.0 0.0"/>
  </link>
  <joint name="base2body" type="fixed">
    <parent link="base_link"/>
    <child link="tank_body"/>
  </joint>
  <link name="tank_body">
    <visual>
      <geometry>
        <box size="0.7 0.35 0.25"/>
      </geometry>
      <origin rpy="0.0 0.0 0.0" xyz="0.0 0.0 0.0"/>
      <material name="blue"/>
    </visual>
  </link>
  <link name="tank_head">
    <visual>
      <geometry>
        <sphere radius="0.125"/>
      </geometry>
      <origin rpy="0.0 0.0 0.0" xyz="0.0 0.0 0.0"/>
      <material name="white"/>
    </visual>
  </link>
  <joint name="body2head" type="continuous">
    <parent link="tank_body"/>
    <child link="tank_head"/>
    <origin rpy="0.0 0.0 0.0" xyz="0.0 0.0 0.125"/>
    <axis xyz="0.0 0.0 1.0"/>
    <limit effort="0.0" lower="0" upper="0" velocity="0.0"/>
  </joint>
  <link name="tank_barrel">
    <visual>
      <geometry>
        <cylinder length="0.35" radius="0.005"/>
      </geometry>
      <origin rpy="0.0 0.0 0.0" xyz="0.0 0.0 0.175"/>
      <material name="green"/>
    </visual>
  </link>
  <joint name="head2barrel" type="revolute">
    <parent link="tank_head"/>
    <child link="tank_barrel"/>
    <origin rpy="0.0 0.7853975 0.0" xyz="0.0883882890117 0.0 0.0883882890117"/>
    <axis xyz="0.0 1.0 0.0"/>
    <limit effort="0.0" lower="0" upper="0.7853975" velocity="12.0"/>
  </joint>
  <link name="tank_right_front_wheel">
    <visual>
      <geometry>
        <cylinder length="0.07" radius="0.125"/>
      </geometry>
      <origin rpy="1.570795 0.0 0.0" xyz="0.0 0.035 0.0"/>
      <material name="black"/>
    </visual>
  </link>
  <joint name="body_2_rf_wheel" type="continuous">
    <parent link="tank_body"/>
    <child link="tank_right_front_wheel"/>
    <origin rpy="0.0 0.0 0.0" xyz="0.175 -0.175 -0.0625"/>
    <axis xyz="0.0 1.0 0.0"/>
    <limit effort="0.0" lower="0" upper="0" velocity="12.0"/>
  </joint>
  <link name="tank_right_back_wheel">
    <visual>
      <geometry>
        <cylinder length="0.07" radius="0.125"/>
      </geometry>
      <origin rpy="1.570795 0.0 0.0" xyz="0.0 0.035 0.0"/>
      <material name="black"/>
    </visual>
  </link>
  <joint name="body_2_rb_wheel" type="continuous">
    <parent link="tank_body"/>
    <child link="tank_right_back_wheel"/>
    <origin rpy="0.0 0.0 0.0" xyz="-0.175 -0.175 -0.0625"/>
    <axis xyz="0.0 1.0 0.0"/>
    <limit effort="0.0" lower="0" upper="0" velocity="12.0"/>
  </joint>
  <link name="tank_left_front_wheel">
    <visual>
      <geometry>
        <cylinder length="0.07" radius="0.125"/>
      </geometry>
      <origin rpy="1.570795 0.0 0.0" xyz="0.0 -0.035 0.0"/>
      <material name="black"/>
    </visual>
  </link>
  <joint name="body_2_lf_wheel" type="continuous">
    <parent link="tank_body"/>
    <child link="tank_left_front_wheel"/>
    <origin rpy="0.0 0.0 0.0" xyz="0.175 0.175 -0.0625"/>
    <axis xyz="0.0 1.0 0.0"/>
    <limit effort="0.0" lower="0" upper="0" velocity="12.0"/>
  </joint>
  <link name="tank_left_back_wheel">
    <visual>
      <geometry>
        <cylinder length="0.07" radius="0.125"/>
      </geometry>
      <origin rpy="1.570795 0.0 0.0" xyz="0.0 -0.035 0.0"/>
      <material name="black"/>
    </visual>
  </link>
  <joint name="body_2_lb_wheel" type="continuous">
    <parent link="tank_body"/>
    <child link="tank_left_back_wheel"/>
    <origin rpy="0.0 0.0 0.0" xyz="-0.175 0.175 -0.0625"/>
    <axis xyz="0.0 1.0 0.0"/>
    <limit effort="0.0" lower="0" upper="0" velocity="12.0"/>
  </joint>
</robot>

