<?xml version="1.0"?>
<robot name="mytank">
    <material name="blue">
        <color rgba="0.0 0.0 0.8 1.0"/>
    </material>
    <material name="white">
        <color rgba="1.0 1.0 1.0 1.0"/>
    </material>
    <material name="red">
        <color rgba="0.8 1.0 1.0 1.0"/>
    </material>

    <material name="green">
        <color rgba="0.0 0.8 0.0 1.0"/>
    </material>
    <material name="black">
        <color rgba="0.0 0.0 0.0 1.0"/>
    </material>

    <link name="base_link">
    <origin xyz="0.0 0.0 0.0" rpy="0.0 0.0 0.0"/>
    </link>

    <joint name="base2body" type="fixed">
        <parent link="base_link"/>
        <child link="tank_body"/>
    </joint>

    <link name="tank_body">
        <visual>
            <geometry>
                <box size="0.7 0.35 0.25"/>
            </geometry>
            <material name="blue" />
        </visual>
    </link>

    <link name="tank_head">
        <visual>
            <geometry>
                <sphere radius="0.1"/>
            </geometry>
            <material name="white" />
        </visual>
    </link>

    <joint name="base2head" type="continuous">
        <parent link="tank_body"/>
        <child link="tank_head"/>
        <origin xyz="0.0 0.0 0.125" rpy="0.0 0.0 0.0"/>
        <axis xyz="0.0 0.0 1.0"/>
    </joint>

    <link name="tank_barrel">
        <visual>
            <geometry>
                <cylinder radius="0.005" length="0.4"/>
            </geometry>
            <origin xyz="0.0 0.0 0.3" rpy="0.0 0.0 0.0"/>
            <material name="green" />
        </visual>
    </link>

    <joint name="head2barrel" type="revolute">
        <parent link="tank_head"/>
        <child link="tank_barrel"/>
        <origin xyz="0.07 0.0 0.07" rpy="0.0 1.1779 0.0"/>
        <limit lower="-0.25" upper="0.25" effort="0.0" velocity="12.0"/>
        <axis xyz="0.0 1.0 0.0"/>
    </joint>

    <link name="right_front_wheel">
        <visual>
            <geometry>
                <cylinder radius="0.1" length="0.075"/>
            </geometry>
        </visual>
        <material name="black">
        </material>
    </link>

    <joint name="body2rightfrontwheel" type="continuous">
        <parent link="tank_body"/>
        <child link="right_front_wheel"/>
        <origin xyz="0.15 -0.1375 -0.075" rpy="1.57075 0.0 0.0"/>
        <axis xyz="0.0 0.0 1.0"/>
    </joint>

    <link name="right_back_wheel">
        <visual>
            <geometry>
                <cylinder radius="0.1" length="0.075"/>
            </geometry>
        </visual>
        <material name="black">
        </material>
    </link>

    <joint name="body2rightbackwheel" type="continuous">
        <parent link="tank_body"/>
        <child link="right_back_wheel"/>
        <origin xyz="-0.15 -0.1375 -0.075" rpy="1.57075 0.0 0.0"/>
        <axis xyz="0.0 0.0 1.0"/>
    </joint>

    <link name="left_front_wheel">
        <visual>
            <geometry>
                <cylinder radius="0.1" length="0.075"/>
            </geometry>
        </visual>
        <material name="black">
        </material>
    </link>

    <joint name="body2leftfrontwheel" type="continuous">
        <parent link="tank_body"/>
        <child link="left_front_wheel"/>
        <origin xyz="0.15 0.1375 -0.075" rpy="1.57075 0.0 0.0"/>
        <axis xyz="0.0 0.0 1.0"/>
    </joint>

    <link name="left_back_wheel">
        <visual>
            <geometry>
                <cylinder radius="0.1" length="0.075"/>
            </geometry>
        </visual>
        <material name="black">
        </material>
    </link>

    <joint name="body2leftbackwheel" type="continuous">
        <parent link="tank_body"/>
        <child link="left_back_wheel"/>
        <origin xyz="-0.15 0.1375 -0.075" rpy="1.57075 0.0 0.0"/>
        <axis xyz="0.0 0.0 1.0"/>
    </joint>
</robot>